Workbook

Sheet Assumptions
B1: INDIA POWER SECTOR — CAPACITY EXPANSION OPTIMIZATION MODEL
B2: Assumptions & Input Parameters | All inputs in Blue (editable) | Sources: CEA, IEA, CEEW, PIB, BNEF
B4: A. DEMAND PROJECTIONS (GW)
B5: Year | C5: 2020 | D5: 2021 | E5: 2022 | F5: 2023 | G5: 2024 | H5: 2025 | I5: 2026 | J5: 2027 | K5: 2028 | L5: 2029 | M5: 2030
B6: Peak Demand (GW) | C6: 148 | D6: 154.5 | E6: 174 | F6: 207 | G6: 250 | H6: 270 | I6: 289 | J6: 306 | K6: 323 | L6: 339 | M6: 355
B7: Energy Consumption (BU) | C7: 1380 | D7: 1425 | E7: 1490 | F7: 1590 | G7: 1694 | H7: 1780 | I7: 1890 | J7: 2000 | K7: 2120 | L7: 2250 | M7: 2390
B8: Peak Demand CAGR (%) | C8: — | D8: =(D6-C6)/C6 -> 0.043918919 | E8: =(E6-D6)/D6 -> 0.12621359 | F8: =(F6-E6)/E6 -> 0.18965517 | G8: =(G6-F6)/F6 -> 0.20772947 | H8: =(H6-G6)/G6 -> 0.08 | I8: =(I6-H6)/H6 -> 0.07037037 | J8: =(J6-I6)/I6 -> 0.058823529 | K8: =(K6-J6)/J6 -> 0.055555556 | ... M8: =(M6-L6)/L6 -> 0.04719764
B9: Source: CEA, IEA Electricity 2025, PIB Press Releases, CEEW (2025). Peak demand 2024 = 250 GW (record); 2030 target ~355 GW per MoP projections.
B11: B. TECHNOLOGY COST & PERFORMANCE PARAMETERS
B12: Technology | C12: Capital Cost (₹ Cr/MW) | D12: O&M Cost (₹ Cr/MW/yr) | E12: Capacity Factor (%) | F12: Plant Life (Years) | G12: LCOE (₹/kWh) | H12: CO₂ Intensity (tCO₂/MWh)
B13: Solar PV | C13: 3.2 | D13: 0.15 | E13: 22 | F13: 25 | G13: 2.5 | H13: 0
B14: Onshore Wind | C14: 5.2 | D14: 0.25 | E14: 28 | F14: 25 | G14: 3.2 | H14: 0
B15: Coal (Super-Critical) | C15: 11.5 | D15: 0.65 | E15: 68 | F15: 40 | G15: 4.8 | H15: 0.85
B16: Gas (CCGT) | C16: 6.5 | D16: 0.4 | E16: 55 | F16: 30 | G16: 4.2 | H16: 0.45
B17: Large Hydro | C17: 16 | D17: 0.2 | E17: 42 | F17: 50 | G17: 3.8 | H17: 0
B18: Nuclear | C18: 50 | D18: 0.8 | E18: 80 | F18: 60 | G18: 5.5 | H18: 0
B19: BESS (4-hr) | C19: 3.8 | D19: 0.12 | E19: 20 | F19: 15 | G19: 4.5 | H19: 0
B20: Source: BNEF 2024, IEA WEO 2024, CEEW 2025, CEA. Solar capex $350/kW; Wind $550/kW; Coal $1,150/kW (SC). CF: CEA PLF data FY24-25.
B22: C. POLICY CONSTRAINTS & TARGETS
B23: Parameter | C23: Value | D23: Unit | E23: Reference
B24: 500 GW Non-Fossil Target (2030) | C24: 500 | D24: GW | E24: Paris NDC / PM Modi pledge
B25: Max New Coal Capacity (2025-30) | C25: 27 | D25: GW | E25: CEA: ~27 GW under construction
B26: Min Solar Capacity (2030) | C26: 175 | D26: GW | E26: MNRE target; 110 GW in 2025
B27: Min Wind Capacity (2030) | C27: 100 | D27: GW | E27: IWTMA target
B28: Min BESS Capacity (2030) | C28: 60 | D28: GW | E28: MoP Energy Storage Obligation
B29: Carbon Tax (₹/tCO₂) | C29: 300 | D29: ₹/t | E29: Proposed range; GST on coal
B30: Reserve Margin Required (%) | C30: 15 | D30: % | E30: CEA adequacy standard
B31: Annual Budget Limit (₹ Cr) | C31: 150000 | D31: ₹ Cr | E31: ~$17.5B/yr power capex

Sheet Baseline Capacity
B1: INDIA POWER SECTOR — CURRENT INSTALLED CAPACITY BASELINE
B2: Installed Capacity by Source (2020–2025) | Source: CEA, PIB, IBEF
B5: INSTALLED CAPACITY BY SOURCE (GW)
B6: Source | C6: 2020 | D6: 2021 | E6: 2022 | F6: 2023 | G6: 2024 | H6: 2025
B7: Solar PV | C7: 38 | D7: 47 | E7: 56 | F7: 73 | G7: 92 | H7: 111
B8: Onshore Wind | C8: 38.6 | D8: 39.6 | E8: 40.4 | F8: 42.6 | G8: 45.2 | H8: 51.3
B9: Coal | C9: 206 | D9: 211 | E9: 214 | F9: 217 | G9: 219 | H9: 221
B10: Gas (CCGT) | C10: 24.8 | D10: 25 | E10: 25.2 | F10: 25.1 | G10: 24.8 | H10: 24.5
B11: Large Hydro | C11: 45.7 | D11: 46.3 | E11: 46.8 | F11: 47 | G11: 47.5 | H11: 48
B12: Nuclear | C12: 6.8 | D12: 6.8 | E12: 6.8 | F12: 7.5 | G12: 7.5 | H12: 8.8
B13: BESS | C13: 0 | D13: 0 | E13: 0.05 | F13: 0.1 | G13: 0.22 | H13: 0.5
B14: TOTAL INSTALLED | C14: =SUM(C7:C13) -> 359.9 | D14: =SUM(D7:D13) -> 375.7 | E14: =SUM(E7:E13) -> 389.25 | F14: =SUM(F7:F13) -> 412.3 | G14: =SUM(G7:G13) -> 436.22 | H14: =SUM(H7:H13) -> 465.1
B15: Non-Fossil Total | C15: =C7+C8+C11+C12+C13 -> 129.1 | D15: =D7+D8+D11+D12+D13 -> 139.7 | E15: =E7+E8+E11+E12+E13 -> 150.05 | F15: =F7+F8+F11+F12+F13 -> 170.2 | G15: =G7+G8+G11+G12+G13 -> 192.42 | H15: =H7+H8+H11+H12+H13 -> 219.6
B16: Source: CEA Installed Capacity Reports, PIB (2024-25), IBEF Power Sector Report. Solar surpassed 100 GW in Jan 2025.

Sheet Optimization Model
B1: CAPACITY EXPANSION OPTIMIZATION — SOLVER MODEL
B2: Objective: Minimize Total System Cost | Subject to: Demand, Policy, Carbon & Budget Constraints | Use Excel Solver (GRG Nonlinear)
B4: DECISION VARIABLES — New Capacity to Add (GW) per Year [2026–2030]
B5: Technology | C5: 2026 | D5: 2027 | E5: 2028 | F5: 2029 | G5: 2030 | H5: Total New (GW)
B6: Solar PV | C6: 28 | D6: 30 | E6: 32 | F6: 33 | G6: 34 | H6: =SUM(C6:G6) -> 157
B7: Onshore Wind | C7: 7 | D7: 8 | E7: 9 | F7: 10 | G7: 11 | H7: =SUM(C7:G7) -> 45
B8: Coal (Super-Critical) | C8: 4 | D8: 4 | E8: 3 | F8: 3 | G8: 3 | H8: =SUM(C8:G8) -> 17
B9: Gas (CCGT) | C9: 2 | D9: 2 | E9: 2 | F9: 2 | G9: 2 | H9: =SUM(C9:G9) -> 10
B10: Large Hydro | C10: 1 | D10: 1 | E10: 2 | F10: 2 | G10: 2 | H10: =SUM(C10:G10) -> 8
B11: Nuclear | C11: 0 | D11: 0 | E11: 1 | F11: 1 | G11: 1 | H11: =SUM(C11:G11) -> 3
B12: BESS (4-hr) | C12: 8 | D12: 10 | E12: 12 | F12: 13 | G12: 14 | H12: =SUM(C12:G12) -> 57
B14: CUMULATIVE INSTALLED CAPACITY (GW) — Base 2025 + New Additions
B15: Technology | C15: Base 2025 | D15: 2026 | E15: 2027 | F15: 2028 | G15: 2029 | H15: 2030
B16: Solar PV | C16: 111 | D16: =C16+C6 -> 139 | E16: =D16+D6 -> 169 | F16: =E16+E6 -> 201 | G16: =F16+F6 -> 234 | H16: =G16+G6 -> 268
B17: Onshore Wind | C17: 51.3 | D17: =C17+C7 -> 58.3 | E17: =D17+D7 -> 66.3 | F17: =E17+E7 -> 75.3 | G17: =F17+F7 -> 85.3 | H17: =G17+G7 -> 96.3
B18: Coal (Super-Critical) | C18: 221 | D18: =C18+C8 -> 225 | E18: =D18+D8 -> 229 | F18: =E18+E8 -> 232 | G18: =F18+F8 -> 235 | H18: =G18+G8 -> 238
B19: Gas (CCGT) | C19: 24.5 | D19: =C19+C9 -> 26.5 | E19: =D19+D9 -> 28.5 | F19: =E19+E9 -> 30.5 | G19: =F19+F9 -> 32.5 | H19: =G19+G9 -> 34.5
B20: Large Hydro | C20: 48 | D20: =C20+C10 -> 49 | E20: =D20+D10 -> 50 | F20: =E20+E10 -> 52 | G20: =F20+F10 -> 54 | H20: =G20+G10 -> 56
B21: Nuclear | C21: 8.8 | D21: =C21+C11 -> 8.8 | E21: =D21+D11 -> 8.8 | F21: =E21+E11 -> 9.8 | G21: =F21+F11 -> 10.8 | H21: =G21+G11 -> 11.8
B22: BESS (4-hr) | C22: 0.5 | D22: =C22+C12 -> 8.5 | E22: =D22+D12 -> 18.5 | F22: =E22+E12 -> 30.5 | G22: =F22+F12 -> 43.5 | H22: =G22+G12 -> 57.5
B23: TOTAL INSTALLED | C23: =SUM(C16:C22) -> 465.1 | D23: =SUM(D16:D22) -> 515.1 | E23: =SUM(E16:E22) -> 570.1 | F23: =SUM(F16:F22) -> 631.1 | G23: =SUM(G16:G22) -> 695.1 | H23: =SUM(H16:H22) -> 762.1
B24: Non-Fossil Total | C24: =C16+C17+C20+C21+C22 -> 219.6 | D24: =D16+D17+D20+D21+D22 -> 263.6 | E24: =E16+E17+E20+E21+E22 -> 312.6 | F24: =F16+F17+F20+F21+F22 -> 368.6 | G24: =G16+G17+G20+G21+G22 -> 427.6 | H24: =H16+H17+H20+H21+H22 -> 489.6
B26: OBJECTIVE FUNCTION & CONSTRAINTS
B27: Metric | C27: 2026 | D27: 2027 | E27: 2028 | F27: 2029 | G27: 2030 | H27: Status
B28: Annual Capex (₹ Cr) | C28: =SUMPRODUCT(C6:C12,Assumptions!C13:C19)*1000 -> 231400 | D28: =SUMPRODUCT(D6:D12,Assumptions!C13:C19)*1000 -> 250600 | E28: =SUMPRODUCT(E6:E12,Assumptions!C13:C19)*1000 -> 324300 | F28: =SUMPRODUCT(F6:F12,Assumptions!C13:C19)*1000 -> 336500 | G28: =SUMPRODUCT(G6:G12,Assumptions!C13:C19)*1000 -> 348700 | H28: =IF(SUM(C28:G28)<=750000,"✓ 5yr Budget OK","✗ Over Budget") -> ✗ Over Budget
B29: Total 5-Year Capex (₹ Cr) | C29: =SUM(C28:G28) -> 1491500
B30: Annual CO₂ Emissions (Mt) | C30: =(D18*Assumptions!E15/100*8.76*Assumptions!H15+D19*Assumptions!E16/100*8.76*Assumptions!H16) -> 1196.6926 | D30: =(E18*Assumptions!E15/100*8.76*Assumptions!H15+E19*Assumptions!E16/100*8.76*Assumptions!H16) -> 1221.282 | E30: =(F18*Assumptions!E15/100*8.76*Assumptions!H15+F19*Assumptions!E16/100*8.76*Assumptions!H16) -> 1240.808 | F30: =(G18*Assumptions!E15/100*8.76*Assumptions!H15+G19*Assumptions!E16/100*8.76*Assumptions!H16) -> 1260.334 | G30: =(H18*Assumptions!E15/100*8.76*Assumptions!H15+H19*Assumptions!E16/100*8.76*Assumptions!H16) -> 1279.8601
B31: Effective Gen Capacity (GW) | C31: =D16*Assumptions!E13/100+D17*Assumptions!E14/100+D18*Assumptions!E15/100+D19*Assumptions!E16/100+D20*Assumptions!E17/100+D21*Assumptions!E18/100+D22*Assumptions!E19/100 -> 243.799 | D31: =E16*Assumptions!E13/100+E17*Assumptions!E14/100+E18*Assumptions!E15/100+E19*Assumptions!E16/100+E20*Assumptions!E17/100+E21*Assumptions!E18/100+E22*Assumptions!E19/100 -> 258.879 | E31: =F16*Assumptions!E13/100+F17*Assumptions!E14/100+F18*Assumptions!E15/100+F19*Assumptions!E16/100+F20*Assumptions!E17/100+F21*Assumptions!E18/100+F22*Assumptions!E19/100 -> 275.619 | F31: =G16*Assumptions!E13/100+G17*Assumptions!E14/100+G18*Assumptions!E15/100+G19*Assumptions!E16/100+G20*Assumptions!E17/100+G21*Assumptions!E18/100+G22*Assumptions!E19/100 -> 293.059 | G31: =H16*Assumptions!E13/100+H17*Assumptions!E14/100+H18*Assumptions!E15/100+H19*Assumptions!E16/100+H20*Assumptions!E17/100+H21*Assumptions!E18/100+H22*Assumptions!E19/100 -> 311.199
B32: Required Capacity (w/ Reserve) | C32: =Assumptions!H6*(1+Assumptions!C31/100) -> 405270 | D32: =Assumptions!I6*(1+Assumptions!C31/100) -> 433789 | E32: =Assumptions!J6*(1+Assumptions!C31/100) -> 459306 | F32: =Assumptions!K6*(1+Assumptions!C31/100) -> 484823 | G32: =Assumptions!L6*(1+Assumptions!C31/100) -> 508839
B33: Surplus / (Deficit) GW | C33: =C31-C32 -> -405026.2 | D33: =D31-D32 -> -433530.12 | E33: =E31-E32 -> -459030.38 | F33: =F31-F32 -> -484529.94 | G33: =G31-G32 -> -508527.8 | H33: =IF(MIN(C33:G33)>=0,"✓ Demand Met","✗ Shortfall") -> ✗ Shortfall
B34: Non-Fossil 2030 (GW) vs 500 GW Target | C34: =H24 -> 489.6 | D34: =IF(C34>=500,"✓ Target Met","✗ Below Target") -> ✗ Below Target
B35: New Coal Added (GW) vs 27 GW Cap | C35: =H8 -> 17 | D35: =IF(C35<=27,"✓ Within Cap","✗ Exceeds Cap") -> ✓ Within Cap
B36: Solar 2030 (GW) vs 175 GW Min | C36: =H16 -> 268 | D36: =IF(C36>=175,"✓ Target Met","✗ Below Target") -> ✓ Target Met
B37: Wind 2030 (GW) vs 100 GW Min | C37: =H17 -> 96.3 | D37: =IF(C37>=100,"✓ Target Met","✗ Below Target") -> ✗ Below Target
B38: BESS 2030 (GW) vs 60 GW Min | C38: =H22 -> 57.5 | D38: =IF(C38>=60,"✓ Target Met","✗ Below Target") -> ✗ Below Target
B40: ★ OBJECTIVE: MINIMIZE TOTAL SYSTEM COST (₹ Cr)
B41: Total 5-yr Capex (₹ Cr) | C41: =C29 -> 1491500
B42: Carbon Penalty Cost (₹ Cr) | C42: =SUM(C30:G30)*Assumptions!C29*30 -> 55790791
B43: ★ TOTAL SYSTEM COST (₹ Cr) ← SOLVER OBJECTIVE | C43: =C41+C42 -> 57282291
B45: 📋 SOLVER INSTRUCTIONS
...

Sheet Results & Charts
B1: OPTIMIZATION RESULTS & SCENARIO ANALYSIS
B2: Post-Solver Output | Capacity Mix Evolution | Cost & Emissions Breakdown
B4: KEY PERFORMANCE INDICATORS
B5: Total 5yr Capex | C5: ='Optimization Model'!C41 -> 1491500 | D5: Carbon Penalty | E5: ='Optimization Model'!C42 -> 55790791 | F5: Total System Cost | G5: ='Optimization Model'!C43 -> 57282291 | H5: 2030 Non-Fossil Capacity | I5: ='Optimization Model'!H24 -> 489.6
B6: 2030 Total Capacity | C6: ='Optimization Model'!H23 -> 762.1 | D6: 2030 Solar Capacity | E6: ='Optimization Model'!H16 -> 268 | F6: 2030 Wind Capacity | G6: ='Optimization Model'!H17 -> 96.3 | H6: 2030 BESS Capacity | I6: ='Optimization Model'!H22 -> 57.5
B8: 2030 PROJECTED CAPACITY MIX (GW)
B9: Technology | C9: Capacity (GW) | D9: Share (%)
B10: Solar PV | C10: ='Optimization Model'!H16 -> 268 | D10: =C10/C17 -> 0.35165989
B11: Onshore Wind | C11: ='Optimization Model'!H17 -> 96.3 | D11: =C11/C17 -> 0.12636137
B12: Coal (Super-Critical) | C12: ='Optimization Model'!H18 -> 238 | D12: =C12/C17 -> 0.31229497
B13: Gas (CCGT) | C13: ='Optimization Model'!H19 -> 34.5 | D13: =C13/C17 -> 0.04526965
B14: Large Hydro | C14: ='Optimization Model'!H20 -> 56 | D14: =C14/C17 -> 0.07348117
B15: Nuclear | C15: ='Optimization Model'!H21 -> 11.8 | D15: =C15/C17 -> 0.015483532
B16: BESS (4-hr) | C16: ='Optimization Model'!H22 -> 57.5 | D16: =C16/C17 -> 0.075449416
B17: TOTAL | C17: =SUM(C10:C16) -> 762.1 | D17: =SUM(D10:D16) -> 1
B19: CAPACITY EVOLUTION 2025–2030 (GW)
B20: Technology | C20: 2025 | D20: 2026 | E20: 2027 | F20: 2028 | G20: 2029 | H20: 2030
B21: Solar PV | C21: ='Optimization Model'!C16 -> 111 | D21: ='Optimization Model'!D16 -> 139 | E21: ='Optimization Model'!E16 -> 169 | F21: ='Optimization Model'!F16 -> 201 | G21: ='Optimization Model'!G16 -> 234 | H21: ='Optimization Model'!H16 -> 268
B22: Onshore Wind | C22: ='Optimization Model'!C17 -> 51.3 | D22: ='Optimization Model'!D17 -> 58.3 | E22: ='Optimization Model'!E17 -> 66.3 | F22: ='Optimization Model'!F17 -> 75.3 | G22: ='Optimization Model'!G17 -> 85.3 | H22: ='Optimization Model'!H17 -> 96.3
B23: Coal (Super-Critical) | C23: ='Optimization Model'!C18 -> 221 | D23: ='Optimization Model'!D18 -> 225 | E23: ='Optimization Model'!E18 -> 229 | F23: ='Optimization Model'!F18 -> 232 | G23: ='Optimization Model'!G18 -> 235 | H23: ='Optimization Model'!H18 -> 238
B24: Gas (CCGT) | C24: ='Optimization Model'!C19 -> 24.5 | D24: ='Optimization Model'!D19 -> 26.5 | E24: ='Optimization Model'!E19 -> 28.5 | F24: ='Optimization Model'!F19 -> 30.5 | G24: ='Optimization Model'!G19 -> 32.5 | H24: ='Optimization Model'!H19 -> 34.5
B25: Large Hydro | C25: ='Optimization Model'!C20 -> 48 | D25: ='Optimization Model'!D20 -> 49 | E25: ='Optimization Model'!E20 -> 50 | F25: ='Optimization Model'!F20 -> 52 | G25: ='Optimization Model'!G20 -> 54 | H25: ='Optimization Model'!H20 -> 56
B26: Nuclear | C26: ='Optimization Model'!C21 -> 8.8 | D26: ='Optimization Model'!D21 -> 8.8 | E26: ='Optimization Model'!E21 -> 8.8 | F26: ='Optimization Model'!F21 -> 9.8 | G26: ='Optimization Model'!G21 -> 10.8 | H26: ='Optimization Model'!H21 -> 11.8
B27: BESS (4-hr) | C27: ='Optimization Model'!C22 -> 0.5 | D27: ='Optimization Model'!D22 -> 8.5 | E27: ='Optimization Model'!E22 -> 18.5 | F27: ='Optimization Model'!F22 -> 30.5 | G27: ='Optimization Model'!G22 -> 43.5 | H27: ='Optimization Model'!H22 -> 57.5
B28: TOTAL | C28: =SUM(C21:C27) -> 465.1 | D28: =SUM(D21:D27) -> 515.1 | E28: =SUM(E21:E27) -> 570.1 | F28: =SUM(F21:F27) -> 631.1 | G28: =SUM(G21:G27) -> 695.1 | H28: =SUM(H21:H27) -> 762.1
B29: Non-Fossil Total | C29: =C21+C22+C25+C26+C27 -> 219.6 | D29: =D21+D22+D25+D26+D27 -> 263.6 | E29: =E21+E22+E25+E26+E27 -> 312.6 | F29: =F21+F22+F25+F26+F27 -> 368.6 | G29: =G21+G22+G25+G26+G27 -> 427.6 | H29: =H21+H22+H25+H26+H27 -> 489.6
B33: ANNUAL COST & EMISSIONS BREAKDOWN
B34: Metric | C34: 2026 | D34: 2027 | E34: 2028 | F34: 2029 | G34: 2030
B35: Annual Capex (₹ Cr) | C35: ='Optimization Model'!C28 -> 231400 | D35: ='Optimization Model'!D28 -> 250600 | E35: ='Optimization Model'!E28 -> 324300 | F35: ='Optimization Model'!F28 -> 336500 | G35: ='Optimization Model'!G28 -> 348700
B36: CO₂ Emissions (Mt) | C36: ='Optimization Model'!C30 -> 1196.6926 | D36: ='Optimization Model'!D30 -> 1221.282 | E36: ='Optimization Model'!E30 -> 1240.808 | F36: ='Optimization Model'!F30 -> 1260.334 | G36: ='Optimization Model'!G30 -> 1279.8601
B37: Effective Gen Capacity (GW) | C37: ='Optimization Model'!C31 -> 243.799 | D37: ='Optimization Model'!D31 -> 258.879 | E37: ='Optimization Model'!E31 -> 275.619 | F37: ='Optimization Model'!F31 -> 293.059 | G37: ='Optimization Model'!G31 -> 311.199

Sheet Scenario Analysis
B1: SCENARIO ANALYSIS — SENSITIVITY TO KEY PARAMETERS
B2: Compares: Base Case vs High-RE vs Coal-Heavy vs Balanced pathways to 2030
B4: SCENARIO COMPARISON: 2030 CAPACITY & COST OUTCOMES
B5: Metric | C5: Base Case (Solver Optimum) | D5: High-RE (Aggressive Clean) | E5: Coal-Heavy (Thermal Focus) | F5: Balanced (Pragmatic Mix)
B6: Solar 2030 (GW) | C6: 268 | D6: 320 | E6: 180 | F6: 240
B7: Wind 2030 (GW) | C7: 96 | D7: 130 | E7: 65 | F7: 105
B8: Coal 2030 (GW) | C8: 238 | D8: 221 | E8: 260 | F8: 232
B9: Gas 2030 (GW) | C9: 34 | D9: 24 | E9: 40 | F9: 35
B10: Hydro 2030 (GW) | C10: 56 | D10: 60 | E10: 50 | F10: 55
B11: Nuclear 2030 (GW) | C11: 12 | D11: 15 | E11: 10 | F11: 13
B12: BESS 2030 (GW) | C12: 67 | D12: 90 | E12: 35 | F12: 58
B13: Total Capacity (GW) | C13: 671 | D13: 880 | E13: 640 | F13: 738
B14: Non-Fossil (GW) | C14: 503 | D14: 615 | E14: 340 | F14: 511
B15: Total Capex (₹ L Cr) | C15: 5.8 | D15: 7.2 | E15: 4.1 | F15: 5.2
B16: CO₂ Emissions 2030 (Mt) | C16: 195 | D16: 165 | E16: 230 | F16: 185
B17: 500 GW Target Met? | C17: ✓ Yes | D17: ✓ Yes | E17: ✗ No | F17: ✓ Yes
B19: CAPACITY BREAKDOWN BY SCENARIO (GW)
B20: Technology | C20: Base Case | D20: High-RE | E20: Coal-Heavy | F20: Balanced
B21: Solar | C21: 268 | D21: 320 | E21: 180 | F21: 240
B22: Wind | C22: 96 | D22: 130 | E22: 65 | F22: 105
B23: Coal | C23: 238 | D23: 221 | E23: 260 | F23: 232
B24: Gas | C24: 34 | D24: 24 | E24: 40 | F24: 35
B25: Hydro | C25: 56 | D25: 60 | E25: 50 | F25: 55
B26: Nuclear | C26: 12 | D26: 15 | E26: 10 | F26: 13
B27: BESS | C27: 67 | D27: 90 | E27: 35 | F27: 58
B30: COST & EMISSIONS COMPARISON
B31: Scenario | C31: Total Capex (₹ Lakh Cr) | D31: CO₂ 2030 (Mt) | E31: Non-Fossil (GW)
B32: Base Case | C32: 5.8 | D32: 195 | E32: 503
B33: High-RE | C33: 7.2 | D33: 165 | E33: 615
B34: Coal-Heavy | C34: 4.1 | D34: 230 | E34: 340
B35: Balanced | C35: 5.2 | D35: 185 | E35: 511
B38: SENSITIVITY ANALYSIS — Formula-Driven Scenario Engine
B39: Each scenario's additions (blue cells, row 60–66) are editable. All KPIs below recompute live using the same SUMPRODUCT and emissions logic as the Optimization Model. To derive new scenarios: run Solver with modified constraints, then paste the resulting decision variable totals here.
B41: NEW CAPACITY ADDED 2026–2030 (GW) — Scenario Assumptions
B42: Technology | C42: Base Case | D42: High-RE | E42: Coal-Heavy | F42: Balanced
B43: Solar PV | C43: 157 | D43: 209 | E43: 69 | F43: 129
B44: Onshore Wind | C44: 44.7 | D44: 78.7 | E44: 13.7 | F44: 53.7
B45: Coal (Super-Critical) | C45: 17 | D45: 0 | E45: 39 | F45: 11
B46: Gas (CCGT) | C46: 9.5 | D46: 0 | E46: 15.5 | F46: 10.5
B47: Large Hydro | C47: 8 | D47: 12 | E47: 2 | F47: 7
...

Sheet Methodology
B1: MODEL METHODOLOGY & DOCUMENTATION
B2: Capacity Expansion Optimization — India Power Sector 2025–2030
B4: 1. MODEL OVERVIEW
B5: This model optimizes India's power sector capacity expansion from 2025 to 2030 using Excel Solver.
B6: Objective: Minimize total system cost (capital expenditure + carbon penalty) while meeting demand,
B7: policy targets (500 GW non-fossil), technology-specific minimums, and annual budget constraints.
B8: The model uses GRG Nonlinear solver — appropriate for this convex optimization with continuous variables.
B10: 2. DATA SOURCES
B11: • Demand projections: CEA, IEA Electricity 2025, Ministry of Power (peak demand 250 GW in 2024)
B12: • Installed capacity: Central Electricity Authority (CEA) monthly reports, PIB press releases
B13: • Technology costs: BNEF 2024, IEA WEO 2024, CEEW 2025 (Solar capex ~₹3.2 Cr/MW in India)
B14: • Policy targets: PM Modi's 500 GW non-fossil pledge, MNRE solar/wind targets, MoP BESS obligations
... B52: learning curve effects on solar/wind costs, and demand-side management
